<?xml version="1.0"?>
<robot xmlns:xacro="http://www.ros.org/wiki/xacro">


  <xacro:if value="$(arg sim)">

      <!-- Include Gazebo Plugin -->
      <xacro:include filename="$(find ommp_description)/urdf/sensors/kinect/kinect.gazebo.xacro" />
      
      <!-- Instantiate it -->
      <xacro:kinect_gazebo_sensor link_name="camera_depth_frame" camera_name="my_camera"
                       frame_name="camera_depth_optical_frame"/>

  </xacro:if>

  	<!-- remove if Kinect isn't moving -->
  	
    <xacro:include filename="$(find ommp_description)/urdf/sensors/kinect/kinect.transmissions.xacro" />

	<!-- Parameterised in part by the values in kinect_properties.urdf.xacro -->

	<xacro:macro name="sensor_kinect" params="parent">

    <joint name="camera_rgb_joint" type="revolute">
      <xacro:insert_block name="kinect_joint_origin" />
      <parent link="${parent}" />
      <child link="camera_rgb_frame" />
      <axis xyz="0 1 0" rpy="0 0 0" />
      <dynamics damping="0.0" friction="0.0"/>
      <limit effort="30" velocity="1.0" lower="-1.57" upper="1.57" />
      <safety_controller k_velocity="10" k_position="15" soft_lower_limit="-1.57" soft_upper_limit="1.57" />
    </joint>

    <link name="camera_rgb_frame">
      <inertial>
        <mass value="0.001" />
        <origin xyz="0 0 0" />
        <inertia ixx="0.0001" ixy="0.0" ixz="0.0"
                 iyy="0.0001" iyz="0.0"
                 izz="0.0001" />
      </inertial>
    </link>
    <joint name="camera_rgb_optical_joint" type="fixed">
      <origin xyz="0 0 0" rpy="${-M_PI/2} 0 ${-M_PI/2}" />
      <parent link="camera_rgb_frame" />
      <child link="camera_rgb_optical_frame" />
    </joint>
    <link name="camera_rgb_optical_frame">
      <inertial>
        <mass value="0.001" />
        <origin xyz="0 0 0" />
        <inertia ixx="0.0001" ixy="0.0" ixz="0.0"
                 iyy="0.0001" iyz="0.0"
                 izz="0.0001" />
      </inertial>
    </link>

  <joint name="camera_joint" type="fixed">
    <origin xyz="-0.031 ${-cam_py} -0.016" rpy="0 0 0"/>
    <parent link="camera_rgb_frame"/>
    <child link="camera_link"/>
  </joint>  
    <link name="camera_link">
    <visual>
     <origin xyz="0 0 0" rpy="0 0 ${M_PI/2}"/>
      <geometry>
       <mesh filename="package://ommp_description/meshes/sensors/kinect/kinect.dae"/>
      </geometry>
    </visual>
	  <collision>
      <origin xyz="0.0 0.0 0.0" rpy="0 0 0"/>
	    <geometry>
	      <box size="0.07271 0.27794 0.073"/>
	    </geometry>
	  </collision>
    <inertial>
      <mass value="0.001" />
      <origin xyz="0 0 0" />
      <inertia ixx="0.0001" ixy="0.0" ixz="0.0"
               iyy="0.0001" iyz="0.0"
               izz="0.0001" />
    </inertial>
  </link>
	  
  <!-- The fixed joints & links below are usually published by static_transformers launched by the OpenNi launch 
       files. However, for Gazebo simulation we need them, so we add them here.
       (Hence, don't publish them additionally!) -->
	<joint name="camera_depth_joint" type="fixed">
	  <origin xyz="0 ${2 * -cam_py} 0" rpy="0 0 0" />
	  <parent link="camera_rgb_frame" />
	  <child link="camera_depth_frame" />
	</joint>
	<link name="camera_depth_frame">
    <inertial>
      <mass value="0.001" />
      <origin xyz="0 0 0" />
      <inertia ixx="0.0001" ixy="0.0" ixz="0.0"
               iyy="0.0001" iyz="0.0"
               izz="0.0001" />
    </inertial>
	</link>
	<joint name="camera_depth_optical_joint" type="fixed">
	  <origin xyz="0 0 0" rpy="${-M_PI/2} 0 ${-M_PI/2}" />
	  <parent link="camera_depth_frame" />
	  <child link="camera_depth_optical_frame" />
	</joint>
	<link name="camera_depth_optical_frame">
    <inertial>
      <mass value="0.001" />
      <origin xyz="0 0 0" />
      <inertia ixx="0.0001" ixy="0.0" ixz="0.0"
               iyy="0.0001" iyz="0.0"
               izz="0.0001" />
    </inertial>
	</link>
	</xacro:macro>

</robot>